Traceback (most recent call last):
  File "/rds/general/user/ak1920/home/fyp/fyp/pytorch_models/time_domain_model.py", line 156, in <module>
    observed_bold = np.loadtxt('/rds/general/user/ak1920/home/fyp/fyp/time_series_take_2/'+fname , delimiter=',')
                    ^^^^^^^^^^^^^^^^^^^^^^^^^^^^^^^^^^^^^^^^^^^^^^^^^^^^^^^^^^^^^^^^^^^^^^^^^^^^^^^^^^^^^^^^^^^^^
  File "/rds/general/user/ak1920/home/anaconda3/envs/pytorch_env/lib/python3.11/site-packages/numpy/lib/npyio.py", line 1373, in loadtxt
    arr = _read(fname, dtype=dtype, comment=comment, delimiter=delimiter,
          ^^^^^^^^^^^^^^^^^^^^^^^^^^^^^^^^^^^^^^^^^^^^^^^^^^^^^^^^^^^^^^^
  File "/rds/general/user/ak1920/home/anaconda3/envs/pytorch_env/lib/python3.11/site-packages/numpy/lib/npyio.py", line 992, in _read
    fh = np.lib._datasource.open(fname, 'rt', encoding=encoding)
         ^^^^^^^^^^^^^^^^^^^^^^^^^^^^^^^^^^^^^^^^^^^^^^^^^^^^^^^
  File "/rds/general/user/ak1920/home/anaconda3/envs/pytorch_env/lib/python3.11/site-packages/numpy/lib/_datasource.py", line 193, in open
    return ds.open(path, mode, encoding=encoding, newline=newline)
           ^^^^^^^^^^^^^^^^^^^^^^^^^^^^^^^^^^^^^^^^^^^^^^^^^^^^^^^
  File "/rds/general/user/ak1920/home/anaconda3/envs/pytorch_env/lib/python3.11/site-packages/numpy/lib/_datasource.py", line 533, in open
    raise FileNotFoundError(f"{path} not found.")
FileNotFoundError: /rds/general/user/ak1920/home/fyp/fyp/time_series_take_2/sub-005-LSD-ROI0.txt not found.
